<mujoco>
	<option timestep="0.0001" integrator="RK4" >
		<flag sensornoise="enable" energy="enable" contact="enable" />
	</option>
	<worldbody>
        <light diffuse=".5 .5 .5" pos="0 0 3" dir="0 0 -1"/>
		<geom type="plane" size="1 1 0.1" rgba=".9 0 0 0.25"/>
		<geom type="sphere" size="0.025" rgba=".9 0 0 0.2" pos="0 0 1.45"/>
		<body pos="0 0 1.25" euler="0 0 0">
			<joint name="pin" type="hinge" axis = "0 -1 0" pos="0 0 0.2"/>
			<geom type="cylinder" size="0.05 0.195" rgba="0 .9 0 1" mass="1"/>
			<body pos="0 0 -0.38" euler="0 0 0">
				<joint name="pin2" type="hinge" axis = "0 -1 0" pos="0 0 0.185"/>
				<geom type="cylinder" size="0.05 0.18" rgba="0 0 .9 1" mass="1"/>
			</body>
		</body>
	</worldbody>

	<actuator>
		<motor joint="pin" name="torque" gear="1" ctrllimited="true" ctrlrange="-100 100" />
		<motor joint="pin2" name="torque2" gear="1" ctrllimited="true" ctrlrange="-100 100" />
	</actuator>
    
</mujoco>